<?xml version="1.0" ?>
<!-- =================================================================================== -->
<!-- |    This document was autogenerated by xacro from urdf/full_body.xacro           | -->
<!-- |    EDITING THIS FILE BY HAND IS NOT RECOMMENDED                                 | -->
<!-- =================================================================================== -->
<robot xmlns:xacro="http://www.ros.org/wiki/xacro" name="full_body">
  <material name="silver">
    <color rgba="0.700 0.700 0.700 1.000"/>
  </material>
  <transmission name="FR_hip_tran">
    <type>transmission_interface/SimpleTransmission</type>
    <joint name="FR_hip">
      <hardwareInterface>hardware_interface/EffortJointInterface</hardwareInterface>
    </joint>
    <actuator name="FR_hip_actr">
      <hardwareInterface>hardware_interface/EffortJointInterface</hardwareInterface>
      <mechanicalReduction>1</mechanicalReduction>
    </actuator>
  </transmission>
  <transmission name="FR_thigh_tran">
    <type>transmission_interface/SimpleTransmission</type>
    <joint name="FR_thigh">
      <hardwareInterface>hardware_interface/EffortJointInterface</hardwareInterface>
    </joint>
    <actuator name="FR_thigh_actr">
      <hardwareInterface>hardware_interface/EffortJointInterface</hardwareInterface>
      <mechanicalReduction>1</mechanicalReduction>
    </actuator>
  </transmission>
  <transmission name="FR_calf_tran">
    <type>transmission_interface/SimpleTransmission</type>
    <joint name="FR_calf">
      <hardwareInterface>hardware_interface/EffortJointInterface</hardwareInterface>
    </joint>
    <actuator name="FR_calf_actr">
      <hardwareInterface>hardware_interface/EffortJointInterface</hardwareInterface>
      <mechanicalReduction>1</mechanicalReduction>
    </actuator>
  </transmission>
  <transmission name="BR_hip_tran">
    <type>transmission_interface/SimpleTransmission</type>
    <joint name="BR_hip">
      <hardwareInterface>hardware_interface/EffortJointInterface</hardwareInterface>
    </joint>
    <actuator name="BR_hip_actr">
      <hardwareInterface>hardware_interface/EffortJointInterface</hardwareInterface>
      <mechanicalReduction>1</mechanicalReduction>
    </actuator>
  </transmission>
  <transmission name="BR_thigh_tran">
    <type>transmission_interface/SimpleTransmission</type>
    <joint name="BR_thigh">
      <hardwareInterface>hardware_interface/EffortJointInterface</hardwareInterface>
    </joint>
    <actuator name="BR_thigh_actr">
      <hardwareInterface>hardware_interface/EffortJointInterface</hardwareInterface>
      <mechanicalReduction>1</mechanicalReduction>
    </actuator>
  </transmission>
  <transmission name="BR_calf_tran">
    <type>transmission_interface/SimpleTransmission</type>
    <joint name="BR_calf">
      <hardwareInterface>hardware_interface/EffortJointInterface</hardwareInterface>
    </joint>
    <actuator name="BR_calf_actr">
      <hardwareInterface>hardware_interface/EffortJointInterface</hardwareInterface>
      <mechanicalReduction>1</mechanicalReduction>
    </actuator>
  </transmission>
  <transmission name="BL_hip_tran">
    <type>transmission_interface/SimpleTransmission</type>
    <joint name="BL_hip">
      <hardwareInterface>hardware_interface/EffortJointInterface</hardwareInterface>
    </joint>
    <actuator name="BL_hip_actr">
      <hardwareInterface>hardware_interface/EffortJointInterface</hardwareInterface>
      <mechanicalReduction>1</mechanicalReduction>
    </actuator>
  </transmission>
  <transmission name="BL_thigh_tran">
    <type>transmission_interface/SimpleTransmission</type>
    <joint name="BL_thigh">
      <hardwareInterface>hardware_interface/EffortJointInterface</hardwareInterface>
    </joint>
    <actuator name="BL_thigh_actr">
      <hardwareInterface>hardware_interface/EffortJointInterface</hardwareInterface>
      <mechanicalReduction>1</mechanicalReduction>
    </actuator>
  </transmission>
  <transmission name="BL_calf_tran">
    <type>transmission_interface/SimpleTransmission</type>
    <joint name="BL_calf">
      <hardwareInterface>hardware_interface/EffortJointInterface</hardwareInterface>
    </joint>
    <actuator name="BL_calf_actr">
      <hardwareInterface>hardware_interface/EffortJointInterface</hardwareInterface>
      <mechanicalReduction>1</mechanicalReduction>
    </actuator>
  </transmission>
  <transmission name="FL_hip_tran">
    <type>transmission_interface/SimpleTransmission</type>
    <joint name="FL_hip">
      <hardwareInterface>hardware_interface/EffortJointInterface</hardwareInterface>
    </joint>
    <actuator name="FL_hip_actr">
      <hardwareInterface>hardware_interface/EffortJointInterface</hardwareInterface>
      <mechanicalReduction>1</mechanicalReduction>
    </actuator>
  </transmission>
  <transmission name="FL_thigh_tran">
    <type>transmission_interface/SimpleTransmission</type>
    <joint name="FL_thigh">
      <hardwareInterface>hardware_interface/EffortJointInterface</hardwareInterface>
    </joint>
    <actuator name="FL_thigh_actr">
      <hardwareInterface>hardware_interface/EffortJointInterface</hardwareInterface>
      <mechanicalReduction>1</mechanicalReduction>
    </actuator>
  </transmission>
  <transmission name="FL_calf_tran">
    <type>transmission_interface/SimpleTransmission</type>
    <joint name="FL_calf">
      <hardwareInterface>hardware_interface/EffortJointInterface</hardwareInterface>
    </joint>
    <actuator name="FL_calf_actr">
      <hardwareInterface>hardware_interface/EffortJointInterface</hardwareInterface>
      <mechanicalReduction>1</mechanicalReduction>
    </actuator>
  </transmission>
  <gazebo>
    <plugin name="control" filename="libgazebo_ros_control.so"/>
  </gazebo>
  <gazebo reference="base_link">
    <material>Gazebo/Silver</material>
    <mu1>0.2</mu1>
    <mu2>0.2</mu2>
    <selfCollide>true</selfCollide>
    <gravity>true</gravity>
  </gazebo>
  <gazebo reference="front_right_hip_1">
    <material>Gazebo/Silver</material>
    <mu1>0.2</mu1>
    <mu2>0.2</mu2>
    <selfCollide>true</selfCollide>
  </gazebo>
  <gazebo reference="front_right_thigh_1">
    <material>Gazebo/Silver</material>
    <mu1>0.2</mu1>
    <mu2>0.2</mu2>
    <selfCollide>true</selfCollide>
  </gazebo>
  <gazebo reference="front_right_calf_1">
    <material>Gazebo/Silver</material>
    <mu1>0.2</mu1>
    <mu2>0.2</mu2>
    <selfCollide>true</selfCollide>
  </gazebo>
  <gazebo reference="back_right_hip_1">
    <material>Gazebo/Silver</material>
    <mu1>0.2</mu1>
    <mu2>0.2</mu2>
    <selfCollide>true</selfCollide>
  </gazebo>
  <gazebo reference="back_right_thigh_1">
    <material>Gazebo/Silver</material>
    <mu1>0.2</mu1>
    <mu2>0.2</mu2>
    <selfCollide>true</selfCollide>
  </gazebo>
  <gazebo reference="back_right_calf_1">
    <material>Gazebo/Silver</material>
    <mu1>0.2</mu1>
    <mu2>0.2</mu2>
    <selfCollide>true</selfCollide>
  </gazebo>
  <gazebo reference="back_left_hip_1">
    <material>Gazebo/Silver</material>
    <mu1>0.2</mu1>
    <mu2>0.2</mu2>
    <selfCollide>true</selfCollide>
  </gazebo>
  <gazebo reference="back_left_thigh_1">
    <material>Gazebo/Silver</material>
    <mu1>0.2</mu1>
    <mu2>0.2</mu2>
    <selfCollide>true</selfCollide>
  </gazebo>
  <gazebo reference="back_left_calf_1">
    <material>Gazebo/Silver</material>
    <mu1>0.2</mu1>
    <mu2>0.2</mu2>
    <selfCollide>true</selfCollide>
  </gazebo>
  <gazebo reference="front_left_hip_1">
    <material>Gazebo/Silver</material>
    <mu1>0.2</mu1>
    <mu2>0.2</mu2>
    <selfCollide>true</selfCollide>
  </gazebo>
  <gazebo reference="front_left_thigh_1">
    <material>Gazebo/Silver</material>
    <mu1>0.2</mu1>
    <mu2>0.2</mu2>
    <selfCollide>true</selfCollide>
  </gazebo>
  <gazebo reference="front_left_calf_1">
    <material>Gazebo/Silver</material>
    <mu1>0.2</mu1>
    <mu2>0.2</mu2>
    <selfCollide>true</selfCollide>
  </gazebo>
  <link name="base_link">
    <inertial>
      <origin xyz="-0.009783288059672884 -0.12747137130856984 0.019319313780907642" rpy="0 0 0"/>
      <mass value="0.25174810750691173"/>
      <inertia ixx="0.000821" iyy="0.000784" izz="0.00117" ixy="1e-06" iyz="2e-06" ixz="-3e-06"/>
    </inertial>
    <visual>
      <origin xyz="0 0 0" rpy="0 0 0"/>
      <geometry>
        <mesh filename="package://full_body_description/meshes/base_link.stl" scale="0.001 0.001 0.001"/>
      </geometry>
      <material name="silver"/>
    </visual>
    <collision>
      <origin xyz="0 0 0" rpy="0 0 0"/>
      <geometry>
        <mesh filename="package://full_body_description/meshes/base_link.stl" scale="0.001 0.001 0.001"/>
      </geometry>
    </collision>
  </link>
  <link name="front_right_hip_1">
    <inertial>
      <origin xyz="0.014838296762223015 -0.025343712502017723 -0.027556197731714076" rpy="0 0 0"/>
      <mass value="0.07326383105165434"/>
      <inertia ixx="3.7e-05" iyy="2.5e-05" izz="3.7e-05" ixy="1e-05" iyz="-2e-06" ixz="2e-06"/>
    </inertial>
    <visual>
      <origin xyz="-0.043129 0.202081 -0.052509" rpy="0 0 0"/>
      <geometry>
        <mesh filename="package://full_body_description/meshes/front_right_hip_1.stl" scale="0.001 0.001 0.001"/>
      </geometry>
      <material name="silver"/>
    </visual>
    <collision>
      <origin xyz="-0.043129 0.202081 -0.052509" rpy="0 0 0"/>
      <geometry>
        <mesh filename="package://full_body_description/meshes/front_right_hip_1.stl" scale="0.001 0.001 0.001"/>
      </geometry>
    </collision>
  </link>
  <link name="front_right_thigh_1">
    <inertial>
      <origin xyz="0.04645622013155958 -0.02403544432134591 0.003395758520891773" rpy="0 0 0"/>
      <mass value="0.043975254567150325"/>
      <inertia ixx="2.2e-05" iyy="2.2e-05" izz="3.9e-05" ixy="0.0" iyz="0.0" ixz="-0.0"/>
    </inertial>
    <visual>
      <origin xyz="-0.045399 0.256492 -0.016413" rpy="0 0 0"/>
      <geometry>
        <mesh filename="package://full_body_description/meshes/front_right_thigh_1.stl" scale="0.001 0.001 0.001"/>
      </geometry>
      <material name="silver"/>
    </visual>
    <collision>
      <origin xyz="-0.045399 0.256492 -0.016413" rpy="0 0 0"/>
      <geometry>
        <mesh filename="package://full_body_description/meshes/front_right_thigh_1.stl" scale="0.001 0.001 0.001"/>
      </geometry>
    </collision>
  </link>
  <link name="front_right_calf_1">
    <inertial>
      <origin xyz="0.020339292125749267 0.014723762097453463 -0.039301824943854695" rpy="0 0 0"/>
      <mass value="0.06443506975038105"/>
      <inertia ixx="8.3e-05" iyy="8.4e-05" izz="9e-06" ixy="-1e-06" iyz="7e-06" ixz="-3e-06"/>
    </inertial>
    <visual>
      <origin xyz="-0.087272 0.324658 -0.016413" rpy="0 0 0"/>
      <geometry>
        <mesh filename="package://full_body_description/meshes/front_right_calf_1.stl" scale="0.001 0.001 0.001"/>
      </geometry>
      <material name="silver"/>
    </visual>
    <collision>
      <origin xyz="-0.087272 0.324658 -0.016413" rpy="0 0 0"/>
      <geometry>
        <mesh filename="package://full_body_description/meshes/front_right_calf_1.stl" scale="0.001 0.001 0.001"/>
      </geometry>
    </collision>
  </link>
  <link name="back_right_hip_1">
    <inertial>
      <origin xyz="-0.014529053797875356 -0.025522745701421795 -0.027556197764197078" rpy="0 0 0"/>
      <mass value="0.07326383109031377"/>
      <inertia ixx="3.7e-05" iyy="2.5e-05" izz="3.7e-05" ixy="-1.1e-05" iyz="-2e-06" ixz="-0.0"/>
    </inertial>
    <visual>
      <origin xyz="0.058276 0.20441 -0.052509" rpy="0 0 0"/>
      <geometry>
        <mesh filename="package://full_body_description/meshes/back_right_hip_1.stl" scale="0.001 0.001 0.001"/>
      </geometry>
      <material name="silver"/>
    </visual>
    <collision>
      <origin xyz="0.058276 0.20441 -0.052509" rpy="0 0 0"/>
      <geometry>
        <mesh filename="package://full_body_description/meshes/back_right_hip_1.stl" scale="0.001 0.001 0.001"/>
      </geometry>
    </collision>
  </link>
  <link name="back_right_thigh_1">
    <inertial>
      <origin xyz="0.0024126058142937556 -0.05224985242728192 0.0033957655301711485" rpy="0 0 0"/>
      <mass value="0.043975104077995854"/>
      <inertia ixx="2.2e-05" iyy="2.2e-05" izz="3.9e-05" ixy="0.0" iyz="0.0" ixz="0.0"/>
    </inertial>
    <visual>
      <origin xyz="0.104262 0.233582 -0.016413" rpy="0 0 0"/>
      <geometry>
        <mesh filename="package://full_body_description/meshes/back_right_thigh_1.stl" scale="0.001 0.001 0.001"/>
      </geometry>
      <material name="silver"/>
    </visual>
    <collision>
      <origin xyz="0.104262 0.233582 -0.016413" rpy="0 0 0"/>
      <geometry>
        <mesh filename="package://full_body_description/meshes/back_right_thigh_1.stl" scale="0.001 0.001 0.001"/>
      </geometry>
    </collision>
  </link>
  <link name="back_right_calf_1">
    <inertial>
      <origin xyz="0.021286869001586453 -0.013263703736651256 -0.03933231200753699" rpy="0 0 0"/>
      <mass value="0.06444549906966254"/>
      <inertia ixx="8.3e-05" iyy="8.5e-05" izz="8e-06" ixy="1e-06" iyz="-0.0" ixz="1e-06"/>
    </inertial>
    <visual>
      <origin xyz="0.142359 0.303928 -0.016413" rpy="0 0 0"/>
      <geometry>
        <mesh filename="package://full_body_description/meshes/back_right_calf_1.stl" scale="0.001 0.001 0.001"/>
      </geometry>
      <material name="silver"/>
    </visual>
    <collision>
      <origin xyz="0.142359 0.303928 -0.016413" rpy="0 0 0"/>
      <geometry>
        <mesh filename="package://full_body_description/meshes/back_right_calf_1.stl" scale="0.001 0.001 0.001"/>
      </geometry>
    </collision>
  </link>
  <link name="back_left_hip_1">
    <inertial>
      <origin xyz="-0.015897574065726672 0.024693707571381264 -0.027556219058615033" rpy="0 0 0"/>
      <mass value="0.07326376312814109"/>
      <inertia ixx="3.6e-05" iyy="2.6e-05" izz="3.7e-05" ixy="1.1e-05" iyz="2e-06" ixz="-1e-06"/>
    </inertial>
    <visual>
      <origin xyz="0.062364 0.053822 -0.052509" rpy="0 0 0"/>
      <geometry>
        <mesh filename="package://full_body_description/meshes/back_left_hip_1.stl" scale="0.001 0.001 0.001"/>
      </geometry>
      <material name="silver"/>
    </visual>
    <collision>
      <origin xyz="0.062364 0.053822 -0.052509" rpy="0 0 0"/>
      <geometry>
        <mesh filename="package://full_body_description/meshes/back_left_hip_1.stl" scale="0.001 0.001 0.001"/>
      </geometry>
    </collision>
  </link>
  <link name="back_left_thigh_1">
    <inertial>
      <origin xyz="-0.0004380348501835385 0.052303344318201356 0.0033965528694622944" rpy="0 0 0"/>
      <mass value="0.04397492344920401"/>
      <inertia ixx="2.2e-05" iyy="2.2e-05" izz="3.9e-05" ixy="0.0" iyz="-0.0" ixz="0.0"/>
    </inertial>
    <visual>
      <origin xyz="0.10987 0.027198 -0.016413" rpy="0 0 0"/>
      <geometry>
        <mesh filename="package://full_body_description/meshes/back_left_thigh_1.stl" scale="0.001 0.001 0.001"/>
      </geometry>
      <material name="silver"/>
    </visual>
    <collision>
      <origin xyz="0.10987 0.027198 -0.016413" rpy="0 0 0"/>
      <geometry>
        <mesh filename="package://full_body_description/meshes/back_left_thigh_1.stl" scale="0.001 0.001 0.001"/>
      </geometry>
    </collision>
  </link>
  <link name="back_left_calf_1">
    <inertial>
      <origin xyz="0.02233090959603723 0.011475768913108482 -0.03931455535825229" rpy="0 0 0"/>
      <mass value="0.06444611273292808"/>
      <inertia ixx="8.3e-05" iyy="8.4e-05" izz="9e-06" ixy="-1e-06" iyz="-6e-06" ixz="5e-06"/>
    </inertial>
    <visual>
      <origin xyz="0.151743 -0.040968 -0.016413" rpy="0 0 0"/>
      <geometry>
        <mesh filename="package://full_body_description/meshes/back_left_calf_1.stl" scale="0.001 0.001 0.001"/>
      </geometry>
      <material name="silver"/>
    </visual>
    <collision>
      <origin xyz="0.151743 -0.040968 -0.016413" rpy="0 0 0"/>
      <geometry>
        <mesh filename="package://full_body_description/meshes/back_left_calf_1.stl" scale="0.001 0.001 0.001"/>
      </geometry>
    </collision>
  </link>
  <link name="front_left_hip_1">
    <inertial>
      <origin xyz="0.013436376575627323 0.026114454274511235 -0.027556219179579518" rpy="0 0 0"/>
      <mass value="0.07326376312539898"/>
      <inertia ixx="3.9e-05" iyy="2.4e-05" izz="3.7e-05" ixy="-1e-05" iyz="2e-06" ixz="2e-06"/>
    </inertial>
    <visual>
      <origin xyz="-0.038966 0.050873 -0.052509" rpy="0 0 0"/>
      <geometry>
        <mesh filename="package://full_body_description/meshes/front_left_hip_1.stl" scale="0.001 0.001 0.001"/>
      </geometry>
      <material name="silver"/>
    </visual>
    <collision>
      <origin xyz="-0.038966 0.050873 -0.052509" rpy="0 0 0"/>
      <geometry>
        <mesh filename="package://full_body_description/meshes/front_left_hip_1.stl" scale="0.001 0.001 0.001"/>
      </geometry>
    </collision>
  </link>
  <link name="front_left_thigh_1">
    <inertial>
      <origin xyz="0.04507689797668257 0.02653036398956253 0.003396546271426059" rpy="0 0 0"/>
      <mass value="0.04397506830368732"/>
      <inertia ixx="2.2e-05" iyy="2.2e-05" izz="3.9e-05" ixy="-0.0" iyz="-0.0" ixz="-0.0"/>
    </inertial>
    <visual>
      <origin xyz="-0.03827 -0.003581 -0.016413" rpy="0 0 0"/>
      <geometry>
        <mesh filename="package://full_body_description/meshes/front_left_thigh_1.stl" scale="0.001 0.001 0.001"/>
      </geometry>
      <material name="silver"/>
    </visual>
    <collision>
      <origin xyz="-0.03827 -0.003581 -0.016413" rpy="0 0 0"/>
      <geometry>
        <mesh filename="package://full_body_description/meshes/front_left_thigh_1.stl" scale="0.001 0.001 0.001"/>
      </geometry>
    </collision>
  </link>
  <link name="front_left_calf_1">
    <inertial>
      <origin xyz="0.02110907579777284 -0.013597346741824924 -0.03929037567662348" rpy="0 0 0"/>
      <mass value="0.0644286979953138"/>
      <inertia ixx="8.3e-05" iyy="8.4e-05" izz="9e-06" ixy="1e-06" iyz="-7e-06" ixz="-2e-06"/>
    </inertial>
    <visual>
      <origin xyz="-0.076367 -0.073927 -0.016413" rpy="0 0 0"/>
      <geometry>
        <mesh filename="package://full_body_description/meshes/front_left_calf_1.stl" scale="0.001 0.001 0.001"/>
      </geometry>
      <material name="silver"/>
    </visual>
    <collision>
      <origin xyz="-0.076367 -0.073927 -0.016413" rpy="0 0 0"/>
      <geometry>
        <mesh filename="package://full_body_description/meshes/front_left_calf_1.stl" scale="0.001 0.001 0.001"/>
      </geometry>
    </collision>
  </link>
  <joint name="FR_hip" type="revolute">
    <origin xyz="0.043129 -0.202081 0.052509" rpy="0 0 0"/>
    <parent link="base_link"/>
    <child link="front_right_hip_1"/>
    <axis xyz="0.0 -0.0 1.0"/>
    <limit upper="0.698132" lower="-0.698132" effort="100" velocity="100"/>
  </joint>
  <joint name="FR_thigh" type="revolute">
    <origin xyz="0.00227 -0.054411 -0.036096" rpy="0 0 0"/>
    <parent link="front_right_hip_1"/>
    <child link="front_right_thigh_1"/>
    <axis xyz="-0.852079 -0.523413 -0.0"/>
    <limit upper="0.698132" lower="-0.698132" effort="100" velocity="100"/>
  </joint>
  <joint name="FR_calf" type="revolute">
    <origin xyz="0.041873 -0.068166 0.0" rpy="0 0 0"/>
    <parent link="front_right_thigh_1"/>
    <child link="front_right_calf_1"/>
    <axis xyz="0.852079 0.523413 0.0"/>
    <limit upper="0.698132" lower="-0.698132" effort="100" velocity="100"/>
  </joint>
  <joint name="BR_hip" type="revolute">
    <origin xyz="-0.058276 -0.20441 0.052509" rpy="0 0 0"/>
    <parent link="base_link"/>
    <child link="back_right_hip_1"/>
    <axis xyz="0.0 -0.0 1.0"/>
    <limit upper="0.698132" lower="-0.698132" effort="100" velocity="100"/>
  </joint>
  <joint name="BR_thigh" type="revolute">
    <origin xyz="-0.045986 -0.029172 -0.036096" rpy="0 0 0"/>
    <parent link="back_right_hip_1"/>
    <child link="back_right_thigh_1"/>
    <axis xyz="-0.879328 0.476216 0.0"/>
    <limit upper="0.698132" lower="-0.698132" effort="100" velocity="100"/>
  </joint>
  <joint name="BR_calf" type="revolute">
    <origin xyz="-0.038097 -0.070346 0.0" rpy="0 0 0"/>
    <parent link="back_right_thigh_1"/>
    <child link="back_right_calf_1"/>
    <axis xyz="0.879328 -0.476216 -0.0"/>
    <limit upper="0.698132" lower="-0.698132" effort="100" velocity="100"/>
  </joint>
  <joint name="BL_hip" type="revolute">
    <origin xyz="-0.062364 -0.053822 0.052509" rpy="0 0 0"/>
    <parent link="base_link"/>
    <child link="back_left_hip_1"/>
    <axis xyz="0.0 -0.0 1.0"/>
    <limit upper="0.698132" lower="-0.698132" effort="100" velocity="100"/>
  </joint>
  <joint name="BL_thigh" type="revolute">
    <origin xyz="-0.047506 0.026624 -0.036096" rpy="0 0 0"/>
    <parent link="back_left_hip_1"/>
    <child link="back_left_thigh_1"/>
    <axis xyz="-0.852079 -0.523413 0.0"/>
    <limit upper="0.698132" lower="-0.698132" effort="100" velocity="100"/>
  </joint>
  <joint name="BL_calf" type="revolute">
    <origin xyz="-0.041873 0.068166 0.0" rpy="0 0 0"/>
    <parent link="back_left_thigh_1"/>
    <child link="back_left_calf_1"/>
    <axis xyz="-0.852079 -0.523413 0.0"/>
    <limit upper="0.698132" lower="-0.698132" effort="100" velocity="100"/>
  </joint>
  <joint name="FL_hip" type="revolute">
    <origin xyz="0.038966 -0.050873 0.052509" rpy="0 0 0"/>
    <parent link="base_link"/>
    <child link="front_left_hip_1"/>
    <axis xyz="0.0 -0.0 1.0"/>
    <limit upper="0.698132" lower="-0.698132" effort="100" velocity="100"/>
  </joint>
  <joint name="FL_thigh" type="revolute">
    <origin xyz="-0.000696 0.054454 -0.036096" rpy="0 0 0"/>
    <parent link="front_left_hip_1"/>
    <child link="front_left_thigh_1"/>
    <axis xyz="-0.879328 0.476216 0.0"/>
    <limit upper="0.698132" lower="-0.698132" effort="100" velocity="100"/>
  </joint>
  <joint name="FL_calf" type="revolute">
    <origin xyz="0.038097 0.070346 0.0" rpy="0 0 0"/>
    <parent link="front_left_thigh_1"/>
    <child link="front_left_calf_1"/>
    <axis xyz="-0.879328 0.476216 0.0"/>
    <limit upper="0.698132" lower="-0.698132" effort="100" velocity="100"/>
  </joint>
</robot>
